Workbook

Sheet Refund Request
A1: Student Name : | B1: =SHACRSE!C1 -> De Freitas, Celina G.
A2: Student ID : | B2: =TEXT(SHACRSE!B1,"00000000") -> 00050666
A3: E-GATE ID : | B3: E1981000077
A4: Programme : | B4: BSW Social Work
A5: Residency : | B5: TnT
A6: Date : | B6: 44998
A8: Semester | B8: Credits | C8: Tuition Charged | D8: College Fee charged | E8: Other Charges | F8: Payment Plan Charge | G8: Total Fees Charged | H8: Total Paid By Student | I8: GATE Application submitted | J8: GATE PAYMENT | K8: Balance to be paid by GATE | L8: Balance to be paid by Student | M8: Comments
A9: 201210 | B9: =SUMIF(SHACRSE!A:A,A9,SHACRSE!J:J) -> 0 | C9: =B9*300 -> 0 | D9: =SUMIFS(TSAAREV!D:D,TSAAREV!C:C,'Refund Request'!A9,TSAAREV!A:A,"*RG")+(SUMIFS(TSAAREV!D:D,TSAAREV!C:C,'Refund Request'!A9,TSAAREV!A:A,"*TE")+(SUMIFS(TSAAREV!D:D,TSAAREV!C:C,'Refund Request'!A9,TSAAREV!A:A,"*GU")+(SUMIFS(TSAAREV!D:D,TSAAREV!C:C,'Refund Request'!A9,TSAAREV!A:A,"*AD")+(SUMIFS(TSAAREV!D:D,TSAAREV!C:C,'Refund Request'!A9,TSAAREV!A:A,"*AC")+(SUMIFS(TSAAREV!D:D,TSAAREV!C:C,'Refund Request'!A9,TSAAREV!A:A,"*LT")))))) -> 0 | E9: =SUMIFS(TSAAREV!D:D,TSAAREV!C:C,'Refund Request'!A9,TSAAREV!A:A,"*")-(SUMIFS(TSAAREV!D:D,TSAAREV!C:C,'Refund Request'!A9,TSAAREV!A:A,"*UG")+(SUMIFS(TSAAREV!D:D,TSAAREV!C:C,'Refund Request'!A9,TSAAREV!A:A,"PLNC")+(SUMIFS(TSAAREV!D:D,TSAAREV!C:C,'Refund Request'!A9,TSAAREV!A:A,"*CS")+(SUMIFS(TSAAREV!D:D,TSAAREV!C:C,'Refund Request'!A9,TSAAREV!A:A,"*RG")+(SUMIFS(TSAAREV!D:D,TSAAREV!C:C,'Refund Request'!A9,TSAAREV!A:A,"*TE")+(SUMIFS(TSAAREV!D:D,TSAAREV!C:C,'Refund Request'!A9,TSAAREV!A:A,"*GU")+(SUMIFS(TSAAREV!D:D,TSAAREV!C:C,'Refund Request'!A9,TSAAREV!A:A,"*AD")+(SUMIFS(TSAAREV!D:D,TSAAREV!C:C,'Refund Request'!A9,TSAAREV!A:A,"*AC")+(SUMIFS(TSAAREV!D:D,TSAAREV!C:C,'Refund Request'!A9,TSAAREV!A:A,"*LT")))))))))) -> 0 | F9: =SUMIFS(TSAAREV!D:D,TSAAREV!C:C,'Refund Request'!A9,TSAAREV!A:A,"PLNC") -> 0 | G9: =SUM(C9:E9) -> 0 | H9: =SUMIFS(TSAAREV!E:E,TSAAREV!C:C,'Refund Request'!A9)-(SUMIFS(TSAAREV!E:E,TSAAREV!C:C,'Refund Request'!A9,TSAAREV!A:A,"GATE")-(SUMIFS(TSAAREV!E:E,TSAAREV!C:C,'Refund Request'!A9,TSAAREV!A:A,"PLNP")-(SUMIFS(TSAAREV!E:E,TSAAREV!C:C,'Refund Request'!A9,TSAAREV!A:A,"PLNM")))) -> 0 | I9: =IF(J9>0,"YES",IF(K9>0,"YES","NO")) -> NO | J9: 0 | K9: 0 | L9: =(G9-H9-J9-K9) -> 0
A10: 201220 | B10: =SUMIF(SHACRSE!A:A,A10,SHACRSE!J:J) -> 0 | C10: =B10*300 -> 0 | D10: =SUMIFS(TSAAREV!D:D,TSAAREV!C:C,'Refund Request'!A10,TSAAREV!A:A,"*RG")+(SUMIFS(TSAAREV!D:D,TSAAREV!C:C,'Refund Request'!A10,TSAAREV!A:A,"*TE")+(SUMIFS(TSAAREV!D:D,TSAAREV!C:C,'Refund Request'!A10,TSAAREV!A:A,"*GU")+(SUMIFS(TSAAREV!D:D,TSAAREV!C:C,'Refund Request'!A10,TSAAREV!A:A,"*AD")+(SUMIFS(TSAAREV!D:D,TSAAREV!C:C,'Refund Request'!A10,TSAAREV!A:A,"*AC")+(SUMIFS(TSAAREV!D:D,TSAAREV!C:C,'Refund Request'!A10,TSAAREV!A:A,"*LT")))))) -> 0 | E10: =SUMIFS(TSAAREV!D:D,TSAAREV!C:C,'Refund Request'!A10,TSAAREV!A:A,"*")-(SUMIFS(TSAAREV!D:D,TSAAREV!C:C,'Refund Request'!A10,TSAAREV!A:A,"*UG")+(SUMIFS(TSAAREV!D:D,TSAAREV!C:C,'Refund Request'!A10,TSAAREV!A:A,"PLNC")+(SUMIFS(TSAAREV!D:D,TSAAREV!C:C,'Refund Request'!A10,TSAAREV!A:A,"*CS")+(SUMIFS(TSAAREV!D:D,TSAAREV!C:C,'Refund Request'!A10,TSAAREV!A:A,"*RG")+(SUMIFS(TSAAREV!D:D,TSAAREV!C:C,'Refund Request'!A10,TSAAREV!A:A,"*TE")+(SUMIFS(TSAAREV!D:D,TSAAREV!C:C,'Refund Request'!A10,TSAAREV!A:A,"*GU")+(SUMIFS(TSAAREV!D:D,TSAAREV!C:C,'Refund Request'!A10,TSAAREV!A:A,"*AD")+(SUMIFS(TSAAREV!D:D,TSAAREV!C:C,'Refund Request'!A10,TSAAREV!A:A,"*AC")+(SUMIFS(TSAAREV!D:D,TSAAREV!C:C,'Refund Request'!A10,TSAAREV!A:A,"*LT")))))))))) -> 0 | F10: =SUMIFS(TSAAREV!D:D,TSAAREV!C:C,'Refund Request'!A10,TSAAREV!A:A,"PLNC") -> 0 | G10: =SUM(C10:E10) -> 0 | H10: =SUMIFS(TSAAREV!E:E,TSAAREV!C:C,'Refund Request'!A10)-(SUMIFS(TSAAREV!E:E,TSAAREV!C:C,'Refund Request'!A10,TSAAREV!A:A,"GATE")-(SUMIFS(TSAAREV!E:E,TSAAREV!C:C,'Refund Request'!A10,TSAAREV!A:A,"PLNP")-(SUMIFS(TSAAREV!E:E,TSAAREV!C:C,'Refund Request'!A10,TSAAREV!A:A,"PLNM")))) -> 0 | I10: =IF(J10>0,"YES",IF(K10>0,"YES","NO")) -> NO | J10: 0 | K10: 0 | L10: =(G10-H10-J10-K10) -> 0
A11: 201230 | B11: =SUMIF(SHACRSE!A:A,A11,SHACRSE!J:J) -> 0 | C11: =B11*300 -> 0 | D11: =SUMIFS(TSAAREV!D:D,TSAAREV!C:C,'Refund Request'!A11,TSAAREV!A:A,"*RG")+(SUMIFS(TSAAREV!D:D,TSAAREV!C:C,'Refund Request'!A11,TSAAREV!A:A,"*TE")+(SUMIFS(TSAAREV!D:D,TSAAREV!C:C,'Refund Request'!A11,TSAAREV!A:A,"*GU")+(SUMIFS(TSAAREV!D:D,TSAAREV!C:C,'Refund Request'!A11,TSAAREV!A:A,"*AD")+(SUMIFS(TSAAREV!D:D,TSAAREV!C:C,'Refund Request'!A11,TSAAREV!A:A,"*AC")+(SUMIFS(TSAAREV!D:D,TSAAREV!C:C,'Refund Request'!A11,TSAAREV!A:A,"*LT")))))) -> 0 | E11: =SUMIFS(TSAAREV!D:D,TSAAREV!C:C,'Refund Request'!A11,TSAAREV!A:A,"*")-(SUMIFS(TSAAREV!D:D,TSAAREV!C:C,'Refund Request'!A11,TSAAREV!A:A,"*UG")+(SUMIFS(TSAAREV!D:D,TSAAREV!C:C,'Refund Request'!A11,TSAAREV!A:A,"PLNC")+(SUMIFS(TSAAREV!D:D,TSAAREV!C:C,'Refund Request'!A11,TSAAREV!A:A,"*CS")+(SUMIFS(TSAAREV!D:D,TSAAREV!C:C,'Refund Request'!A11,TSAAREV!A:A,"*RG")+(SUMIFS(TSAAREV!D:D,TSAAREV!C:C,'Refund Request'!A11,TSAAREV!A:A,"*TE")+(SUMIFS(TSAAREV!D:D,TSAAREV!C:C,'Refund Request'!A11,TSAAREV!A:A,"*GU")+(SUMIFS(TSAAREV!D:D,TSAAREV!C:C,'Refund Request'!A11,TSAAREV!A:A,"*AD")+(SUMIFS(TSAAREV!D:D,TSAAREV!C:C,'Refund Request'!A11,TSAAREV!A:A,"*AC")+(SUMIFS(TSAAREV!D:D,TSAAREV!C:C,'Refund Request'!A11,TSAAREV!A:A,"*LT")))))))))) -> 0 | F11: =SUMIFS(TSAAREV!D:D,TSAAREV!C:C,'Refund Request'!A11,TSAAREV!A:A,"PLNC") -> 0 | G11: =SUM(C11:E11) -> 0 | H11: =SUMIFS(TSAAREV!E:E,TSAAREV!C:C,'Refund Request'!A11)-(SUMIFS(TSAAREV!E:E,TSAAREV!C:C,'Refund Request'!A11,TSAAREV!A:A,"GATE")-(SUMIFS(TSAAREV!E:E,TSAAREV!C:C,'Refund Request'!A11,TSAAREV!A:A,"PLNP")-(SUMIFS(TSAAREV!E:E,TSAAREV!C:C,'Refund Request'!A11,TSAAREV!A:A,"PLNM")))) -> 0 | I11: =IF(J11>0,"YES",IF(K11>0,"YES","NO")) -> NO | J11: 0 | K11: 0 | L11: =(G11-H11-J11-K11) -> 0
A12: 201310 | B12: =SUMIF(SHACRSE!A:A,A12,SHACRSE!J:J) -> 12 | C12: =B12*300 -> 3600 | D12: =SUMIFS(TSAAREV!D:D,TSAAREV!C:C,'Refund Request'!A12,TSAAREV!A:A,"*RG")+(SUMIFS(TSAAREV!D:D,TSAAREV!C:C,'Refund Request'!A12,TSAAREV!A:A,"*TE")+(SUMIFS(TSAAREV!D:D,TSAAREV!C:C,'Refund Request'!A12,TSAAREV!A:A,"*GU")+(SUMIFS(TSAAREV!D:D,TSAAREV!C:C,'Refund Request'!A12,TSAAREV!A:A,"*AD")+(SUMIFS(TSAAREV!D:D,TSAAREV!C:C,'Refund Request'!A12,TSAAREV!A:A,"*AC")+(SUMIFS(TSAAREV!D:D,TSAAREV!C:C,'Refund Request'!A12,TSAAREV!A:A,"*LT")))))) -> 410 | E12: =SUMIFS(TSAAREV!D:D,TSAAREV!C:C,'Refund Request'!A12,TSAAREV!A:A,"*")-(SUMIFS(TSAAREV!D:D,TSAAREV!C:C,'Refund Request'!A12,TSAAREV!A:A,"*UG")+(SUMIFS(TSAAREV!D:D,TSAAREV!C:C,'Refund Request'!A12,TSAAREV!A:A,"PLNC")+(SUMIFS(TSAAREV!D:D,TSAAREV!C:C,'Refund Request'!A12,TSAAREV!A:A,"*CS")+(SUMIFS(TSAAREV!D:D,TSAAREV!C:C,'Refund Request'!A12,TSAAREV!A:A,"*RG")+(SUMIFS(TSAAREV!D:D,TSAAREV!C:C,'Refund Request'!A12,TSAAREV!A:A,"*TE")+(SUMIFS(TSAAREV!D:D,TSAAREV!C:C,'Refund Request'!A12,TSAAREV!A:A,"*GU")+(SUMIFS(TSAAREV!D:D,TSAAREV!C:C,'Refund Request'!A12,TSAAREV!A:A,"*AD")+(SUMIFS(TSAAREV!D:D,TSAAREV!C:C,'Refund Request'!A12,TSAAREV!A:A,"*AC")+(SUMIFS(TSAAREV!D:D,TSAAREV!C:C,'Refund Request'!A12,TSAAREV!A:A,"*LT")))))))))) -> 59 | F12: =SUMIFS(TSAAREV!D:D,TSAAREV!C:C,'Refund Request'!A12,TSAAREV!A:A,"PLNC") -> 0 | G12: =SUM(C12:E12) -> 4069 | H12: =SUMIFS(TSAAREV!E:E,TSAAREV!C:C,'Refund Request'!A12)-(SUMIFS(TSAAREV!E:E,TSAAREV!C:C,'Refund Request'!A12,TSAAREV!A:A,"GATE")-(SUMIFS(TSAAREV!E:E,TSAAREV!C:C,'Refund Request'!A12,TSAAREV!A:A,"PLNP")-(SUMIFS(TSAAREV!E:E,TSAAREV!C:C,'Refund Request'!A12,TSAAREV!A:A,"PLNM")))) -> 469 | I12: =IF(J12>0,"YES",IF(K12>0,"YES","NO")) -> NO | J12: 0 | K12: 0 | L12: =(G12-H12-J12-K12) -> 3600
A13: 201320 | B13: =SUMIF(SHACRSE!A:A,A13,SHACRSE!J:J) -> 9 | C13: =B13*300 -> 2700 | D13: =SUMIFS(TSAAREV!D:D,TSAAREV!C:C,'Refund Request'!A13,TSAAREV!A:A,"*RG")+(SUMIFS(TSAAREV!D:D,TSAAREV!C:C,'Refund Request'!A13,TSAAREV!A:A,"*TE")+(SUMIFS(TSAAREV!D:D,TSAAREV!C:C,'Refund Request'!A13,TSAAREV!A:A,"*GU")+(SUMIFS(TSAAREV!D:D,TSAAREV!C:C,'Refund Request'!A13,TSAAREV!A:A,"*AD")+(SUMIFS(TSAAREV!D:D,TSAAREV!C:C,'Refund Request'!A13,TSAAREV!A:A,"*AC")+(SUMIFS(TSAAREV!D:D,TSAAREV!C:C,'Refund Request'!A13,TSAAREV!A:A,"*LT")))))) -> 280 | E13: =SUMIFS(TSAAREV!D:D,TSAAREV!C:C,'Refund Request'!A13,TSAAREV!A:A,"*")-(SUMIFS(TSAAREV!D:D,TSAAREV!C:C,'Refund Request'!A13,TSAAREV!A:A,"*UG")+(SUMIFS(TSAAREV!D:D,TSAAREV!C:C,'Refund Request'!A13,TSAAREV!A:A,"PLNC")+(SUMIFS(TSAAREV!D:D,TSAAREV!C:C,'Refund Request'!A13,TSAAREV!A:A,"*CS")+(SUMIFS(TSAAREV!D:D,TSAAREV!C:C,'Refund Request'!A13,TSAAREV!A:A,"*RG")+(SUMIFS(TSAAREV!D:D,TSAAREV!C:C,'Refund Request'!A13,TSAAREV!A:A,"*TE")+(SUMIFS(TSAAREV!D:D,TSAAREV!C:C,'Refund Request'!A13,TSAAREV!A:A,"*GU")+(SUMIFS(TSAAREV!D:D,TSAAREV!C:C,'Refund Request'!A13,TSAAREV!A:A,"*AD")+(SUMIFS(TSAAREV!D:D,TSAAREV!C:C,'Refund Request'!A13,TSAAREV!A:A,"*AC")+(SUMIFS(TSAAREV!D:D,TSAAREV!C:C,'Refund Request'!A13,TSAAREV!A:A,"*LT")))))))))) -> 15 | F13: =SUMIFS(TSAAREV!D:D,TSAAREV!C:C,'Refund Request'!A13,TSAAREV!A:A,"PLNC") -> 0 | G13: =SUM(C13:E13) -> 2995 | H13: =SUMIFS(TSAAREV!E:E,TSAAREV!C:C,'Refund Request'!A13)-(SUMIFS(TSAAREV!E:E,TSAAREV!C:C,'Refund Request'!A13,TSAAREV!A:A,"GATE")-(SUMIFS(TSAAREV!E:E,TSAAREV!C:C,'Refund Request'!A13,TSAAREV!A:A,"PLNP")-(SUMIFS(TSAAREV!E:E,TSAAREV!C:C,'Refund Request'!A13,TSAAREV!A:A,"PLNM")))) -> 295 | I13: =IF(J13>0,"YES",IF(K13>0,"YES","NO")) -> NO | J13: 0 | K13: 0 | L13: =(G13-H13-J13-K13) -> 2700
A14: 201330 | B14: =SUMIF(SHACRSE!A:A,A14,SHACRSE!J:J) -> 3 | C14: =B14*300 -> 900 | D14: =SUMIFS(TSAAREV!D:D,TSAAREV!C:C,'Refund Request'!A14,TSAAREV!A:A,"*RG")+(SUMIFS(TSAAREV!D:D,TSAAREV!C:C,'Refund Request'!A14,TSAAREV!A:A,"*TE")+(SUMIFS(TSAAREV!D:D,TSAAREV!C:C,'Refund Request'!A14,TSAAREV!A:A,"*GU")+(SUMIFS(TSAAREV!D:D,TSAAREV!C:C,'Refund Request'!A14,TSAAREV!A:A,"*AD")+(SUMIFS(TSAAREV!D:D,TSAAREV!C:C,'Refund Request'!A14,TSAAREV!A:A,"*AC")+(SUMIFS(TSAAREV!D:D,TSAAREV!C:C,'Refund Request'!A14,TSAAREV!A:A,"*LT")))))) -> 280 | E14: =SUMIFS(TSAAREV!D:D,TSAAREV!C:C,'Refund Request'!A14,TSAAREV!A:A,"*")-(SUMIFS(TSAAREV!D:D,TSAAREV!C:C,'Refund Request'!A14,TSAAREV!A:A,"*UG")+(SUMIFS(TSAAREV!D:D,TSAAREV!C:C,'Refund Request'!A14,TSAAREV!A:A,"PLNC")+(SUMIFS(TSAAREV!D:D,TSAAREV!C:C,'Refund Request'!A14,TSAAREV!A:A,"*CS")+(SUMIFS(TSAAREV!D:D,TSAAREV!C:C,'Refund Request'!A14,TSAAREV!A:A,"*RG")+(SUMIFS(TSAAREV!D:D,TSAAREV!C:C,'Refund Request'!A14,TSAAREV!A:A,"*TE")+(SUMIFS(TSAAREV!D:D,TSAAREV!C:C,'Refund Request'!A14,TSAAREV!A:A,"*GU")+(SUMIFS(TSAAREV!D:D,TSAAREV!C:C,'Refund Request'!A14,TSAAREV!A:A,"*AD")+(SUMIFS(TSAAREV!D:D,TSAAREV!C:C,'Refund Request'!A14,TSAAREV!A:A,"*AC")+(SUMIFS(TSAAREV!D:D,TSAAREV!C:C,'Refund Request'!A14,TSAAREV!A:A,"*LT")))))))))) -> 0 | F14: =SUMIFS(TSAAREV!D:D,TSAAREV!C:C,'Refund Request'!A14,TSAAREV!A:A,"PLNC") -> 0 | G14: =SUM(C14:E14) -> 1180 | H14: =SUMIFS(TSAAREV!E:E,TSAAREV!C:C,'Refund Request'!A14)-(SUMIFS(TSAAREV!E:E,TSAAREV!C:C,'Refund Request'!A14,TSAAREV!A:A,"GATE")-(SUMIFS(TSAAREV!E:E,TSAAREV!C:C,'Refund Request'!A14,TSAAREV!A:A,"PLNP")-(SUMIFS(TSAAREV!E:E,TSAAREV!C:C,'Refund Request'!A14,TSAAREV!A:A,"PLNM")))) -> 1180 | I14: =IF(J14>0,"YES",IF(K14>0,"YES","NO")) -> NO | J14: 0 | K14: 0 | L14: =(G14-H14-J14-K14) -> 0
A15: 201410 | B15: =SUMIF(SHACRSE!A:A,A15,SHACRSE!J:J) -> 0 | C15: =B15*300 -> 0 | D15: =SUMIFS(TSAAREV!D:D,TSAAREV!C:C,'Refund Request'!A15,TSAAREV!A:A,"*RG")+(SUMIFS(TSAAREV!D:D,TSAAREV!C:C,'Refund Request'!A15,TSAAREV!A:A,"*TE")+(SUMIFS(TSAAREV!D:D,TSAAREV!C:C,'Refund Request'!A15,TSAAREV!A:A,"*GU")+(SUMIFS(TSAAREV!D:D,TSAAREV!C:C,'Refund Request'!A15,TSAAREV!A:A,"*AD")+(SUMIFS(TSAAREV!D:D,TSAAREV!C:C,'Refund Request'!A15,TSAAREV!A:A,"*AC")+(SUMIFS(TSAAREV!D:D,TSAAREV!C:C,'Refund Request'!A15,TSAAREV!A:A,"*LT")))))) -> 460 | E15: =SUMIFS(TSAAREV!D:D,TSAAREV!C:C,'Refund Request'!A15,TSAAREV!A:A,"*")-(SUMIFS(TSAAREV!D:D,TSAAREV!C:C,'Refund Request'!A15,TSAAREV!A:A,"*UG")+(SUMIFS(TSAAREV!D:D,TSAAREV!C:C,'Refund Request'!A15,TSAAREV!A:A,"PLNC")+(SUMIFS(TSAAREV!D:D,TSAAREV!C:C,'Refund Request'!A15,TSAAREV!A:A,"*CS")+(SUMIFS(TSAAREV!D:D,TSAAREV!C:C,'Refund Request'!A15,TSAAREV!A:A,"*RG")+(SUMIFS(TSAAREV!D:D,TSAAREV!C:C,'Refund Request'!A15,TSAAREV!A:A,"*TE")+(SUMIFS(TSAAREV!D:D,TSAAREV!C:C,'Refund Request'!A15,TSAAREV!A:A,"*GU")+(SUMIFS(TSAAREV!D:D,TSAAREV!C:C,'Refund Request'!A15,TSAAREV!A:A,"*AD")+(SUMIFS(TSAAREV!D:D,TSAAREV!C:C,'Refund Request'!A15,TSAAREV!A:A,"*AC")+(SUMIFS(TSAAREV!D:D,TSAAREV!C:C,'Refund Request'!A15,TSAAREV!A:A,"*LT")))))))))) -> 900 | F15: =SUMIFS(TSAAREV!D:D,TSAAREV!C:C,'Refund Request'!A15,TSAAREV!A:A,"PLNC") -> 0 | G15: =SUM(C15:E15) -> 1360 | H15: =SUMIFS(TSAAREV!E:E,TSAAREV!C:C,'Refund Request'!A15)-(SUMIFS(TSAAREV!E:E,TSAAREV!C:C,'Refund Request'!A15,TSAAREV!A:A,"GATE")-(SUMIFS(TSAAREV!E:E,TSAAREV!C:C,'Refund Request'!A15,TSAAREV!A:A,"PLNP")-(SUMIFS(TSAAREV!E:E,TSAAREV!C:C,'Refund Request'!A15,TSAAREV!A:A,"PLNM")))) -> 1360 | I15: =IF(J15>0,"YES",IF(K15>0,"YES","NO")) -> NO | J15: 0 | K15: 0 | L15: =(G15-H15-J15-K15) -> 0
A16: 201420 | B16: =SUMIF(SHACRSE!A:A,A16,SHACRSE!J:J) -> 0 | C16: =B16*300 -> 0 | D16: =SUMIFS(TSAAREV!D:D,TSAAREV!C:C,'Refund Request'!A16,TSAAREV!A:A,"*RG")+(SUMIFS(TSAAREV!D:D,TSAAREV!C:C,'Refund Request'!A16,TSAAREV!A:A,"*TE")+(SUMIFS(TSAAREV!D:D,TSAAREV!C:C,'Refund Request'!A16,TSAAREV!A:A,"*GU")+(SUMIFS(TSAAREV!D:D,TSAAREV!C:C,'Refund Request'!A16,TSAAREV!A:A,"*AD")+(SUMIFS(TSAAREV!D:D,TSAAREV!C:C,'Refund Request'!A16,TSAAREV!A:A,"*AC")+(SUMIFS(TSAAREV!D:D,TSAAREV!C:C,'Refund Request'!A16,TSAAREV!A:A,"*LT")))))) -> 0 | E16: =SUMIFS(TSAAREV!D:D,TSAAREV!C:C,'Refund Request'!A16,TSAAREV!A:A,"*")-(SUMIFS(TSAAREV!D:D,TSAAREV!C:C,'Refund Request'!A16,TSAAREV!A:A,"*UG")+(SUMIFS(TSAAREV!D:D,TSAAREV!C:C,'Refund Request'!A16,TSAAREV!A:A,"PLNC")+(SUMIFS(TSAAREV!D:D,TSAAREV!C:C,'Refund Request'!A16,TSAAREV!A:A,"*CS")+(SUMIFS(TSAAREV!D:D,TSAAREV!C:C,'Refund Request'!A16,TSAAREV!A:A,"*RG")+(SUMIFS(TSAAREV!D:D,TSAAREV!C:C,'Refund Request'!A16,TSAAREV!A:A,"*TE")+(SUMIFS(TSAAREV!D:D,TSAAREV!C:C,'Refund Request'!A16,TSAAREV!A:A,"*GU")+(SUMIFS(TSAAREV!D:D,TSAAREV!C:C,'Refund Request'!A16,TSAAREV!A:A,"*AD")+(SUMIFS(TSAAREV!D:D,TSAAREV!C:C,'Refund Request'!A16,TSAAREV!A:A,"*AC")+(SUMIFS(TSAAREV!D:D,TSAAREV!C:C,'Refund Request'!A16,TSAAREV!A:A,"*LT")))))))))) -> 0 | F16: =SUMIFS(TSAAREV!D:D,TSAAREV!C:C,'Refund Request'!A16,TSAAREV!A:A,"PLNC") -> 0 | G16: =SUM(C16:E16) -> 0 | H16: =SUMIFS(TSAAREV!E:E,TSAAREV!C:C,'Refund Request'!A16)-(SUMIFS(TSAAREV!E:E,TSAAREV!C:C,'Refund Request'!A16,TSAAREV!A:A,"GATE")-(SUMIFS(TSAAREV!E:E,TSAAREV!C:C,'Refund Request'!A16,TSAAREV!A:A,"PLNP")-(SUMIFS(TSAAREV!E:E,TSAAREV!C:C,'Refund Request'!A16,TSAAREV!A:A,"PLNM")))) -> 0 | I16: =IF(J16>0,"YES",IF(K16>0,"YES","NO")) -> NO | J16: 0 | K16: 0 | L16: =(G16-H16-J16-K16) -> 0
A17: 201430 | B17: =SUMIF(SHACRSE!A:A,A17,SHACRSE!J:J) -> 0 | C17: =B17*300 -> 0 | D17: =SUMIFS(TSAAREV!D:D,TSAAREV!C:C,'Refund Request'!A17,TSAAREV!A:A,"*RG")+(SUMIFS(TSAAREV!D:D,TSAAREV!C:C,'Refund Request'!A17,TSAAREV!A:A,"*TE")+(SUMIFS(TSAAREV!D:D,TSAAREV!C:C,'Refund Request'!A17,TSAAREV!A:A,"*GU")+(SUMIFS(TSAAREV!D:D,TSAAREV!C:C,'Refund Request'!A17,TSAAREV!A:A,"*AD")+(SUMIFS(TSAAREV!D:D,TSAAREV!C:C,'Refund Request'!A17,TSAAREV!A:A,"*AC")+(SUMIFS(TSAAREV!D:D,TSAAREV!C:C,'Refund Request'!A17,TSAAREV!A:A,"*LT")))))) -> 0 | E17: =SUMIFS(TSAAREV!D:D,TSAAREV!C:C,'Refund Request'!A17,TSAAREV!A:A,"*")-(SUMIFS(TSAAREV!D:D,TSAAREV!C:C,'Refund Request'!A17,TSAAREV!A:A,"*UG")+(SUMIFS(TSAAREV!D:D,TSAAREV!C:C,'Refund Request'!A17,TSAAREV!A:A,"PLNC")+(SUMIFS(TSAAREV!D:D,TSAAREV!C:C,'Refund Request'!A17,TSAAREV!A:A,"*CS")+(SUMIFS(TSAAREV!D:D,TSAAREV!C:C,'Refund Request'!A17,TSAAREV!A:A,"*RG")+(SUMIFS(TSAAREV!D:D,TSAAREV!C:C,'Refund Request'!A17,TSAAREV!A:A,"*TE")+(SUMIFS(TSAAREV!D:D,TSAAREV!C:C,'Refund Request'!A17,TSAAREV!A:A,"*GU")+(SUMIFS(TSAAREV!D:D,TSAAREV!C:C,'Refund Request'!A17,TSAAREV!A:A,"*AD")+(SUMIFS(TSAAREV!D:D,TSAAREV!C:C,'Refund Request'!A17,TSAAREV!A:A,"*AC")+(SUMIFS(TSAAREV!D:D,TSAAREV!C:C,'Refund Request'!A17,TSAAREV!A:A,"*LT")))))))))) -> 0 | F17: =SUMIFS(TSAAREV!D:D,TSAAREV!C:C,'Refund Request'!A17,TSAAREV!A:A,"PLNC") -> 0 | G17: =SUM(C17:E17) -> 0 | H17: =SUMIFS(TSAAREV!E:E,TSAAREV!C:C,'Refund Request'!A17)-(SUMIFS(TSAAREV!E:E,TSAAREV!C:C,'Refund Request'!A17,TSAAREV!A:A,"GATE")-(SUMIFS(TSAAREV!E:E,TSAAREV!C:C,'Refund Request'!A17,TSAAREV!A:A,"PLNP")-(SUMIFS(TSAAREV!E:E,TSAAREV!C:C,'Refund Request'!A17,TSAAREV!A:A,"PLNM")))) -> 0 | I17: =IF(J17>0,"YES",IF(K17>0,"YES","NO")) -> NO | J17: 0 | K17: 0 | L17: =(G17-H17-J17-K17) -> 0
A18: 201510 | B18: =SUMIF(SHACRSE!A:A,A18,SHACRSE!J:J) -> 0 | C18: =B18*300 -> 0 | D18: =SUMIFS(TSAAREV!D:D,TSAAREV!C:C,'Refund Request'!A18,TSAAREV!A:A,"*RG")+(SUMIFS(TSAAREV!D:D,TSAAREV!C:C,'Refund Request'!A18,TSAAREV!A:A,"*TE")+(SUMIFS(TSAAREV!D:D,TSAAREV!C:C,'Refund Request'!A18,TSAAREV!A:A,"*GU")+(SUMIFS(TSAAREV!D:D,TSAAREV!C:C,'Refund Request'!A18,TSAAREV!A:A,"*AD")+(SUMIFS(TSAAREV!D:D,TSAAREV!C:C,'Refund Request'!A18,TSAAREV!A:A,"*AC")+(SUMIFS(TSAAREV!D:D,TSAAREV!C:C,'Refund Request'!A18,TSAAREV!A:A,"*LT")))))) -> 0 | E18: =SUMIFS(TSAAREV!D:D,TSAAREV!C:C,'Refund Request'!A18,TSAAREV!A:A,"*")-(SUMIFS(TSAAREV!D:D,TSAAREV!C:C,'Refund Request'!A18,TSAAREV!A:A,"*UG")+(SUMIFS(TSAAREV!D:D,TSAAREV!C:C,'Refund Request'!A18,TSAAREV!A:A,"PLNC")+(SUMIFS(TSAAREV!D:D,TSAAREV!C:C,'Refund Request'!A18,TSAAREV!A:A,"*CS")+(SUMIFS(TSAAREV!D:D,TSAAREV!C:C,'Refund Request'!A18,TSAAREV!A:A,"*RG")+(SUMIFS(TSAAREV!D:D,TSAAREV!C:C,'Refund Request'!A18,TSAAREV!A:A,"*TE")+(SUMIFS(TSAAREV!D:D,TSAAREV!C:C,'Refund Request'!A18,TSAAREV!A:A,"*GU")+(SUMIFS(TSAAREV!D:D,TSAAREV!C:C,'Refund Request'!A18,TSAAREV!A:A,"*AD")+(SUMIFS(TSAAREV!D:D,TSAAREV!C:C,'Refund Request'!A18,TSAAREV!A:A,"*AC")+(SUMIFS(TSAAREV!D:D,TSAAREV!C:C,'Refund Request'!A18,TSAAREV!A:A,"*LT")))))))))) -> 0 | F18: =SUMIFS(TSAAREV!D:D,TSAAREV!C:C,'Refund Request'!A18,TSAAREV!A:A,"PLNC") -> 0 | G18: =SUM(C18:E18) -> 0 | H18: =SUMIFS(TSAAREV!E:E,TSAAREV!C:C,'Refund Request'!A18)-(SUMIFS(TSAAREV!E:E,TSAAREV!C:C,'Refund Request'!A18,TSAAREV!A:A,"GATE")-(SUMIFS(TSAAREV!E:E,TSAAREV!C:C,'Refund Request'!A18,TSAAREV!A:A,"PLNP")-(SUMIFS(TSAAREV!E:E,TSAAREV!C:C,'Refund Request'!A18,TSAAREV!A:A,"PLNM")))) -> 0 | I18: =IF(J18>0,"YES",IF(K18>0,"YES","NO")) -> NO | J18: 0 | K18: 0 | L18: =(G18-H18-J18-K18) -> 0
A19: 201520 | B19: =SUMIF(SHACRSE!A:A,A19,SHACRSE!J:J) -> 0 | C19: =B19*300 -> 0 | D19: =SUMIFS(TSAAREV!D:D,TSAAREV!C:C,'Refund Request'!A19,TSAAREV!A:A,"*RG")+(SUMIFS(TSAAREV!D:D,TSAAREV!C:C,'Refund Request'!A19,TSAAREV!A:A,"*TE")+(SUMIFS(TSAAREV!D:D,TSAAREV!C:C,'Refund Request'!A19,TSAAREV!A:A,"*GU")+(SUMIFS(TSAAREV!D:D,TSAAREV!C:C,'Refund Request'!A19,TSAAREV!A:A,"*AD")+(SUMIFS(TSAAREV!D:D,TSAAREV!C:C,'Refund Request'!A19,TSAAREV!A:A,"*AC")+(SUMIFS(TSAAREV!D:D,TSAAREV!C:C,'Refund Request'!A19,TSAAREV!A:A,"*LT")))))) -> 0 | E19: =SUMIFS(TSAAREV!D:D,TSAAREV!C:C,'Refund Request'!A19,TSAAREV!A:A,"*")-(SUMIFS(TSAAREV!D:D,TSAAREV!C:C,'Refund Request'!A19,TSAAREV!A:A,"*UG")+(SUMIFS(TSAAREV!D:D,TSAAREV!C:C,'Refund Request'!A19,TSAAREV!A:A,"PLNC")+(SUMIFS(TSAAREV!D:D,TSAAREV!C:C,'Refund Request'!A19,TSAAREV!A:A,"*CS")+(SUMIFS(TSAAREV!D:D,TSAAREV!C:C,'Refund Request'!A19,TSAAREV!A:A,"*RG")+(SUMIFS(TSAAREV!D:D,TSAAREV!C:C,'Refund Request'!A19,TSAAREV!A:A,"*TE")+(SUMIFS(TSAAREV!D:D,TSAAREV!C:C,'Refund Request'!A19,TSAAREV!A:A,"*GU")+(SUMIFS(TSAAREV!D:D,TSAAREV!C:C,'Refund Request'!A19,TSAAREV!A:A,"*AD")+(SUMIFS(TSAAREV!D:D,TSAAREV!C:C,'Refund Request'!A19,TSAAREV!A:A,"*AC")+(SUMIFS(TSAAREV!D:D,TSAAREV!C:C,'Refund Request'!A19,TSAAREV!A:A,"*LT")))))))))) -> 10 | F19: =SUMIFS(TSAAREV!D:D,TSAAREV!C:C,'Refund Request'!A19,TSAAREV!A:A,"PLNC") -> 0 | G19: =SUM(C19:E19) -> 10 | H19: =SUMIFS(TSAAREV!E:E,TSAAREV!C:C,'Refund Request'!A19)-(SUMIFS(TSAAREV!E:E,TSAAREV!C:C,'Refund Request'!A19,TSAAREV!A:A,"GATE")-(SUMIFS(TSAAREV!E:E,TSAAREV!C:C,'Refund Request'!A19,TSAAREV!A:A,"PLNP")-(SUMIFS(TSAAREV!E:E,TSAAREV!C:C,'Refund Request'!A19,TSAAREV!A:A,"PLNM")))) -> 10 | I19: =IF(J19>0,"YES",IF(K19>0,"YES","NO")) -> NO | J19: 0 | K19: 0 | L19: =(G19-H19-J19-K19) -> 0
A20: 201530 | B20: =SUMIF(SHACRSE!A:A,A20,SHACRSE!J:J) -> 6 | C20: =B20*300 -> 1800 | D20: =SUMIFS(TSAAREV!D:D,TSAAREV!C:C,'Refund Request'!A20,TSAAREV!A:A,"*RG")+(SUMIFS(TSAAREV!D:D,TSAAREV!C:C,'Refund Request'!A20,TSAAREV!A:A,"*TE")+(SUMIFS(TSAAREV!D:D,TSAAREV!C:C,'Refund Request'!A20,TSAAREV!A:A,"*GU")+(SUMIFS(TSAAREV!D:D,TSAAREV!C:C,'Refund Request'!A20,TSAAREV!A:A,"*AD")+(SUMIFS(TSAAREV!D:D,TSAAREV!C:C,'Refund Request'!A20,TSAAREV!A:A,"*AC")+(SUMIFS(TSAAREV!D:D,TSAAREV!C:C,'Refund Request'!A20,TSAAREV!A:A,"*LT")))))) -> 0 | E20: =SUMIFS(TSAAREV!D:D,TSAAREV!C:C,'Refund Request'!A20,TSAAREV!A:A,"*")-(SUMIFS(TSAAREV!D:D,TSAAREV!C:C,'Refund Request'!A20,TSAAREV!A:A,"*UG")+(SUMIFS(TSAAREV!D:D,TSAAREV!C:C,'Refund Request'!A20,TSAAREV!A:A,"PLNC")+(SUMIFS(TSAAREV!D:D,TSAAREV!C:C,'Refund Request'!A20,TSAAREV!A:A,"*CS")+(SUMIFS(TSAAREV!D:D,TSAAREV!C:C,'Refund Request'!A20,TSAAREV!A:A,"*RG")+(SUMIFS(TSAAREV!D:D,TSAAREV!C:C,'Refund Request'!A20,TSAAREV!A:A,"*TE")+(SUMIFS(TSAAREV!D:D,TSAAREV!C:C,'Refund Request'!A20,TSAAREV!A:A,"*GU")+(SUMIFS(TSAAREV!D:D,TSAAREV!C:C,'Refund Request'!A20,TSAAREV!A:A,"*AD")+(SUMIFS(TSAAREV!D:D,TSAAREV!C:C,'Refund Request'!A20,TSAAREV!A:A,"*AC")+(SUMIFS(TSAAREV!D:D,TSAAREV!C:C,'Refund Request'!A20,TSAAREV!A:A,"*LT")))))))))) -> 0 | F20: =SUMIFS(TSAAREV!D:D,TSAAREV!C:C,'Refund Request'!A20,TSAAREV!A:A,"PLNC") -> 0 | G20: =SUM(C20:E20) -> 1800 | H20: =SUMIFS(TSAAREV!E:E,TSAAREV!C:C,'Refund Request'!A20)-(SUMIFS(TSAAREV!E:E,TSAAREV!C:C,'Refund Request'!A20,TSAAREV!A:A,"GATE")-(SUMIFS(TSAAREV!E:E,TSAAREV!C:C,'Refund Request'!A20,TSAAREV!A:A,"PLNP")-(SUMIFS(TSAAREV!E:E,TSAAREV!C:C,'Refund Request'!A20,TSAAREV!A:A,"PLNM")))) -> 0 | I20: =IF(J20>0,"YES",IF(K20>0,"YES","NO")) -> NO | J20: 0 | K20: 0 | L20: =(G20-H20-J20-K20) -> 1800
... A40: 202320 | B40: =SUMIF(SHACRSE!A:A,A40,SHACRSE!J:J) -> 0 | C40: =B40*300 -> 0 | D40: =SUMIFS(TSAAREV!D:D,TSAAREV!C:C,'Refund Request'!A40,TSAAREV!A:A,"*RG")+(SUMIFS(TSAAREV!D:D,TSAAREV!C:C,'Refund Request'!A40,TSAAREV!A:A,"*TE")+(SUMIFS(TSAAREV!D:D,TSAAREV!C:C,'Refund Request'!A40,TSAAREV!A:A,"*GU")+(SUMIFS(TSAAREV!D:D,TSAAREV!C:C,'Refund Request'!A40,TSAAREV!A:A,"*AD")+(SUMIFS(TSAAREV!D:D,TSAAREV!C:C,'Refund Request'!A40,TSAAREV!A:A,"*AC")+(SUMIFS(TSAAREV!D:D,TSAAREV!C:C,'Refund Request'!A40,TSAAREV!A:A,"*LT")))))) -> 0 | E40: =SUMIFS(TSAAREV!D:D,TSAAREV!C:C,'Refund Request'!A40,TSAAREV!A:A,"*")-(SUMIFS(TSAAREV!D:D,TSAAREV!C:C,'Refund Request'!A40,TSAAREV!A:A,"*UG")+(SUMIFS(TSAAREV!D:D,TSAAREV!C:C,'Refund Request'!A40,TSAAREV!A:A,"PLNC")+(SUMIFS(TSAAREV!D:D,TSAAREV!C:C,'Refund Request'!A40,TSAAREV!A:A,"*CS")+(SUMIFS(TSAAREV!D:D,TSAAREV!C:C,'Refund Request'!A40,TSAAREV!A:A,"*RG")+(SUMIFS(TSAAREV!D:D,TSAAREV!C:C,'Refund Request'!A40,TSAAREV!A:A,"*TE")+(SUMIFS(TSAAREV!D:D,TSAAREV!C:C,'Refund Request'!A40,TSAAREV!A:A,"*GU")+(SUMIFS(TSAAREV!D:D,TSAAREV!C:C,'Refund Request'!A40,TSAAREV!A:A,"*AD")+(SUMIFS(TSAAREV!D:D,TSAAREV!C:C,'Refund Request'!A40,TSAAREV!A:A,"*AC")+(SUMIFS(TSAAREV!D:D,TSAAREV!C:C,'Refund Request'!A40,TSAAREV!A:A,"*LT")))))))))) -> 0 | F40: =SUMIFS(TSAAREV!D:D,TSAAREV!C:C,'Refund Request'!A40,TSAAREV!A:A,"PLNC") -> 0 | G40: =SUM(C40:E40) -> 0 | H40: =SUMIFS(TSAAREV!E:E,TSAAREV!C:C,'Refund Request'!A40)-(SUMIFS(TSAAREV!E:E,TSAAREV!C:C,'Refund Request'!A40,TSAAREV!A:A,"GATE")-(SUMIFS(TSAAREV!E:E,TSAAREV!C:C,'Refund Request'!A40,TSAAREV!A:A,"PLNP")-(SUMIFS(TSAAREV!E:E,TSAAREV!C:C,'Refund Request'!A40,TSAAREV!A:A,"PLNM")))) -> 0 | I40: =IF(J40>0,"YES",IF(K40>0,"YES","NO")) -> NO | J40: 0 | K40: 0 | L40: =(G40-H40-J40-K40) -> 0
B41: =SUM(B9:B40) -> 135 | C41: =SUM(C9:C40) -> 40500 | D41: =SUM(D9:D40) -> 5080 | E41: =SUM(E9:E40) -> 1682 | F41: =SUM(F9:F40) -> 0 | G41: =SUM(G9:G40) -> 47262 | H41: =SUM(H9:H40) -> 14862 | J41: =SUM(J9:J40) -> 0 | K41: =SUM(K9:K40) -> 0 | L41: =SUM(L9:L40) -> 32400
A43: Confirmed By:

Sheet SHACRSE
B1: 50666 | C1: De Freitas, Celina G.
A2: =IF(K2="W","",B2) -> 201310 | B2: 201310 | C2: 1 | D2: CC | E2: CS | F2: 12689 | G2: BIOL | H2: 90 | I2: C04 | J2: 3 | K2: C+ | L2: C | N2: Intro to Concepts in Bio I
A3: =IF(K3="W","",B3) -> 201310 | B3: 201310 | C3: 1 | D3: CC | E3: CS | F3: 12593 | G3: MATH | H3: 91 | I3: C09 | J3: 3 | K3: D+ | L3: C | N3: Pre-Algebra
A4: =IF(K4="W","",B4) -> 201310 | B4: 201310 | C4: 1 | D4: CS | E4: CS | F4: 13040 | G4: PHYS | H4: 90 | I4: S01 | J4: 3 | K4: D | L4: C | N4: Intro to Concepts in Physics I
A5: =IF(K5="W","",B5) -> 201310 | B5: 201310 | C5: 1 | D5: CC | E5: CS | F5: 12245 | G5: WRIT | H5: 95 | I5: C05 | J5: 3 | K5: B | L5: C | N5: Intro to Academic Writing II
A6: =IF(K6="W","",B6) -> 201320 | B6: 201320 | C6: 1 | D6: CC | E6: CS | F6: 25212 | G6: BIOL | H6: 92 | I6: C01 | J6: 3 | K6: D+ | L6: C | N6: Intro to Concepts in Bio II
A7: =IF(K7="W","",B7) -> 201320 | B7: 201320 | C7: 1 | D7: CC | E7: CS | F7: 24999 | G7: MATH | H7: 92 | I7: C07 | J7: 3 | K7: D | L7: C | N7: Basic Algebra
A8: =IF(K8="W","",B8) -> 201320 | B8: 201320 | C8: 1 | D8: CC | E8: CS | F8: 25339 | G8: WRIT | H8: 97 | I8: C01 | J8: 3 | K8: C | L8: C | N8: Intro to Academic Writing III
A9: =IF(K9="W","",B9) -> 201330 | B9: 201330 | C9: 1 | D9: CC | E9: UG | F9: 36828 | G9: COMM | H9: 117 | I9: C04 | J9: 3 | K9: C+ | L9: S | N9: Fundamentals of Writing
A10: =IF(K10="W","",B10) | B10: 201410 | C10: 1 | D10: CC | E10: CS | F10: 14876 | G10: PHYS | H10: 92 | I10: C02 | J10: 3 | K10: W | L10: C | N10: Intro to Concepts in Phys II
A11: =IF(K11="W","",B11) -> 201720 | B11: 201720 | C11: 1 | D11: CC | E11: UG | F11: 22919 | G11: BIOL | H11: 113 | I11: C01 | J11: 3 | K11: C+ | L11: S | N11: Intro to Anatomy & Physiology
A12: =IF(K12="W","",B12) -> 201720 | B12: 201720 | C12: 1 | D12: CS | E12: UG | F12: 22004 | G12: COMM | H12: 118 | I12: S03 | J12: 3 | K12: A | L12: S | N12: Communication in the Workplace
A13: =IF(K13="W","",B13) -> 201730 | B13: 201730 | C13: 1 | D13: CS | E13: UG | F13: 31467 | G13: ENVH | H13: 220 | I13: S01 | J13: 3 | K13: C | L13: S | N13: Food & Food Hygiene I
... A16: =IF(K16="W","",B16) -> 201810 | B16: 201810 | C16: 1 | D16: CE | E16: UG | F16: 14288 | G16: HLED | H16: 100 | I16: E01 | J16: 3 | K16: B | L16: S | N16: First Aid & Occupational Hlth.
A17: =IF(K17="W","",B17) -> 201810 | B17: 201810 | C17: 1 | D17: CC | E17: CS | F17: 14474 | G17: MATH | H17: 93 | I17: C01 | J17: 3 | K17: F | L17: C | M17: E | N17: Intermediate Algebra
A18: =IF(K18="W","",B18) -> 201820 | B18: 201820 | C18: 1 | D18: CC | E18: UG | F18: 24338 | G18: ENVH | H18: 223 | I18: C01 | J18: 3 | K18: B | L18: S | N18: Envh Hlth Admin & Legislation
A19: =IF(K19="W","",B19) -> 201820 | B19: 201820 | C19: 1 | D19: CS | E19: UG | F19: 23753 | G19: LIBS | H19: 130 | I19: S04 | J19: 3 | K19: B+ | L19: S | N19: Fundamental Research Skills
A20: =IF(K20="W","",B20) -> 201820 | B20: 201820 | C20: 1 | D20: CC | E20: CS | F20: 24005 | G20: MATH | H20: 93 | I20: C03 | J20: 3 | K20: D+ | L20: C | M20: I | N20: Intermediate Algebra
A21: =IF(K21="W","",B21) -> 201820 | B21: 201820 | C21: 1 | D21: CS | E21: UG | F21: 24311 | G21: SCIE | H21: 121 | I21: S02 | J21: 3 | K21: A | L21: S | N21: Foundations of Natural Science
A22: =IF(K22="W","",B22) -> 201910 | B22: 201910 | C22: 1 | D22: CC | E22: UG | F22: 16432 | G22: ENVH | H22: 136 | I22: C01 | J22: 3 | K22: B+ | L22: S | N22: Community Health I
A23: =IF(K23="W","",B23) -> 201910 | B23: 201910 | C23: 1 | D23: CC | E23: UG | F23: 16430 | G23: ENVS | H23: 215 | I23: C01 | J23: 3 | K23: C+ | L23: S | N23: Disaster Management
A24: =IF(K24="W","",B24) -> 201910 | B24: 201910 | C24: 1 | D24: CC | E24: UG | F24: 16810 | G24: HIST | H24: 210 | I24: C04 | J24: 3 | K24: B | L24: S | N24: History of Trinidad & Tobago
A25: =IF(K25="W","",B25) -> 201910 | B25: 201910 | C25: 1 | D25: CC | E25: UG | F25: 16205 | G25: MATH | H25: 117 | I25: C01 | J25: 3 | K25: F | L25: S | M25: E | N25: College Algebra
A26: =IF(K26="W","",B26) -> 201920 | B26: 201920 | C26: 1 | D26: CC | E26: UG | F26: 25909 | G26: ENVH | H26: 124 | I26: C01 | J26: 3 | K26: B | L26: S | N26: Epidemiology
A27: =IF(K27="W","",B27) -> 201920 | B27: 201920 | C27: 1 | D27: CC | E27: UG | F27: 25733 | G27: ENVH | H27: 211 | I27: C01 | J27: 3 | K27: C+ | L27: S | N27: Building Sci & Construction
A28: =IF(K28="W","",B28) -> 201920 | B28: 201920 | C28: 1 | D28: CC | E28: UG | F28: 25741 | G28: ENVS | H28: 121 | I28: C01 | J28: 1 | K28: B | L28: S | N28: Envn Issues & Sustainability
A29: =IF(K29="W","",B29) -> 201930 | B29: 201930 | C29: 1 | D29: CC | E29: UG | F29: 33075 | G29: MATH | H29: 117 | I29: C01 | J29: 3 | K29: D+ | L29: S | M29: I | N29: College Algebra
A30: =IF(K30="W","",B30) -> 202010 | B30: 202010 | C30: 1 | D30: CC | E30: UG | F30: 17988 | G30: ENVH | H30: 212 | I30: C01 | J30: 3 | K30: C | L30: S | N30: Environmental Health I
A31: =IF(K31="W","",B31) -> 202010 | B31: 202010 | C31: 1 | D31: CC | E31: UG | F31: 17949 | G31: STAT | H31: 120 | I31: C04 | J31: 3 | K31: C+ | L31: S | N31: Fundamentals of Statistics
A32: =IF(K32="W","",B32) -> 202020 | B32: 202020 | C32: 1 | D32: CC | E32: UG | F32: 27191 | G32: ENVH | H32: 122 | I32: C01 | J32: 3 | K32: C | L32: S | N32: Vector Control
A33: =IF(K33="W","",B33) -> 202020 | B33: 202020 | C33: 1 | D33: CC | E33: UG | F33: 27170 | G33: ENVH | H33: 213 | I33: C01 | J33: 3 | K33: B | L33: S | N33: Environmental Health II
A34: =IF(K34="W","",B34) -> 202120 | B34: 202120 | C34: 1 | D34: CC | E34: UG | F34: 20459 | G34: ENVH | H34: 266 | I34: C01 | J34: 6 | K34: B+ | L34: S | N34: Environ. Health Internship
A35: =IF(K35="W","",B35) -> 202310 | B35: 202310 | C35: 1 | D35: CH | E35: UG | F35: 19492 | G35: NURS | H35: 320 | I35: H02 | J35: 3 | K35: D | L35: S | N35: Pathophysiology II
A36: =IF(K36="W","",B36) -> 201530 | B36: 201530 | C36: 1 | D36: CT | E36: UG | F36: 30582 | G36: NURS | H36: 334 | I36: T01 | J36: 3 | K36: B | L36: S | N36: Adult Nursing
A37: =IF(K37="W","",B37) -> 201530 | B37: 201530 | C37: 1 | D37: CE | E37: UG | F37: 30046 | G37: NURS | H37: 337 | I37: D01 | J37: 3 | K37: C+ | L37: S | N37: Nursing Informatics
A38: =IF(K38="W","",B38) -> 201610 | B38: 201610 | C38: 1 | D38: CT | E38: UG | F38: 11129 | G38: NURS | H38: 260 | I38: T01 | J38: 3 | K38: A | L38: S | N38: Nutrition and Disease
A39: =IF(K39="W","",B39) -> 201610 | B39: 201610 | C39: 1 | D39: CT | E39: UG | F39: 11255 | G39: NURS | H39: 275 | I39: T01 | J39: 3 | K39: C+ | L39: S | N39: Pharmacology in Nursing
A40: =IF(K40="W","",B40) -> 201610 | B40: 201610 | C40: 1 | D40: CT | E40: UG | F40: 11228 | G40: NURS | H40: 411 | I40: T01 | J40: 3 | K40: B+ | L40: S | N40: Pro. Devlpment & Mgmt
A41: =IF(K41="W","",B41) -> 201610 | B41: 201610 | C41: 1 | D41: CT | E41: UG | F41: 11271 | G41: NURS | H41: 499 | I41: T01 | J41: 4 | K41: C+ | L41: S | N41: Senior Project- Nursing
... A47: =IF(K47="W","",B47) -> 201810 | B47: 201810 | C47: 1 | D47: CT | E47: UG | F47: 13863 | G47: NURS | H47: 373 | I47: T01 | J47: 2 | K47: A | L47: S | N47: Clinic Exp & Lvl III Prac Exm
...

Sheet TSAAREV
C1: 50666 | D1: Mrs Celina Glenda De Freitas | H1: KKMARTINEAUOJT
A2: GATE | B2: GATE Payment | C2: 201310 | E2: 900 | F2: 0 | G2: C | H2: 44039.571 | I2: 44039.571 | O2: 253 | T2: F | U2: F0018149 | V2: 44046 | W2: EPUJADAS | X2: 5 | Y2: 44039.634 | Z2: 44039.571
A3: GATE | B3: GATE Payment | C3: 201310 | E3: 2700 | F3: 0 | G3: C | H3: 44039.571 | I3: 44039.571 | O3: 252 | T3: F | U3: F0018149 | V3: 44046 | W3: EPUJADAS | X3: 5 | Y3: 44039.634 | Z3: 44039.571
A4: GATE | B4: GATE Payment | C4: 201310 | E4: -3600 | F4: 0 | G4: C | H4: 44039.571 | I4: 44039.571 | O4: 251 | T4: F | U4: F0018149 | V4: 44046 | W4: EPUJADAS | X4: 5 | Y4: 44039.634 | Z4: 44039.571
A5: GATE | B5: GATE Payment CORR | C5: 201310 | E5: 3600 | F5: 0 | G5: C | H5: 43192.365 | I5: 43192.365 | O5: 147 | T5: F | W5: SAISUSR | X5: 2 | Y5: 43792.549 | Z5: 43192.365
A6: CASH | B6: Cash Payment | C6: 201310 | E6: 15 | F6: 0 | G6: T | H6: 41206 | I6: 41206 | L6: 216146 | O6: 56 | T6: F | U6: F0004846 | V6: 41207 | W6: FCAMERON | X6: 1270 | Y6: 41206.583 | Z6: 41206.468
A7: MCLB | B7: Library Revenue | C7: 201310 | D7: 15 | F7: 0 | G7: T | H7: 41206 | I7: 41206 | L7: 216146 | O7: 55 | T7: F | U7: F0004846 | V7: 41207 | W7: FCAMERON | X7: 1270 | Y7: 41206.583 | Z7: 41206.468
A8: CCPR | B8: City Campus-Printing Fee | C8: 201310 | D8: 40 | F8: 0 | G8: T | H8: 41205 | I8: 41205 | L8: 216028 | O8: 54 | T8: F | U8: F0004838 | V8: 41205 | W8: LBENJAMIN | X8: 553 | Y8: 41205.584 | Z8: 41205.479
A9: CASH | B9: Cash Payment | C9: 201310 | E9: 40 | F9: 0 | G9: T | H9: 41205 | I9: 41205 | L9: 216028 | O9: 53 | T9: F | U9: F0004838 | V9: 41205 | W9: LBENJAMIN | X9: 553 | Y9: 41205.584 | Z9: 41205.478
A10: MCLB | B10: Library Revenue | C10: 201310 | D10: 4 | F10: 0 | G10: T | H10: 41199 | I10: 41199 | L10: 215535 | O10: 52 | T10: F | U10: F0004796 | V10: 41200 | W10: LBENJAMIN | X10: 547 | Y10: 41199.587 | Z10: 41199.5
A11: CASH | B11: Cash Payment | C11: 201310 | E11: 4 | F11: 0 | G11: T | H11: 41199 | I11: 41199 | L11: 215535 | O11: 51 | T11: F | U11: F0004796 | V11: 41200 | W11: LBENJAMIN | X11: 547 | Y11: 41199.587 | Z11: 41199.5
A12: CCCS | B12: City Campus-Compass Program | C12: 201310 | D12: -900 | F12: 0 | G12: R | H12: 41155.59 | I12: 41155.59 | O12: 50 | T12: F | U12: F0015931 | V12: 43510 | W12: WWW_USER | X12: 59 | Y12: 42626.967 | Z12: 41155.59
A13: CCCS | B13: City Campus-Compass Program | C13: 201310 | D13: 900 | F13: 0 | G13: R | H13: 41155.59 | I13: 41155.59 | O13: 49 | T13: F | U13: F0015931 | V13: 43510 | W13: WWW_USER | X13: 59 | Y13: 42626.967 | Z13: 41155.59
A14: CCCS | B14: City Campus-Compass Program | C14: 201310 | D14: 900 | F14: 0 | G14: R | H14: 41149.866 | I14: 41149.866 | O14: 48 | T14: F | U14: F0015930 | V14: 43510 | W14: WWW_USER | X14: 59 | Y14: 42626.967 | Z14: 41149.866
A15: CCCS | B15: City Campus-Compass Program | C15: 201310 | D15: -900 | F15: 0 | G15: R | H15: 41149.848 | I15: 41149.848 | O15: 47 | T15: F | U15: F0015930 | V15: 43510 | W15: WWW_USER | X15: 59 | Y15: 42626.967 | Z15: 41149.848
A16: CCCS | B16: City Campus-Compass Program | C16: 201310 | D16: -900 | F16: 0 | G16: R | H16: 41149.848 | I16: 41149.848 | O16: 46 | T16: F | U16: F0015930 | V16: 43510 | W16: WWW_USER | X16: 59 | Y16: 42626.967 | Z16: 41149.848
A17: CCCS | B17: City Campus-Compass Program | C17: 201310 | D17: 900 | F17: 0 | G17: R | H17: 41149.848 | I17: 41149.848 | O17: 45 | T17: F | U17: F0015930 | V17: 43510 | W17: WWW_USER | X17: 59 | Y17: 42626.967 | Z17: 41149.848
A18: CCCS | B18: City Campus-Compass Program | C18: 201310 | D18: 900 | F18: 0 | G18: R | H18: 41149.832 | I18: 41149.832 | O18: 44 | T18: F | U18: F0015930 | V18: 43510 | W18: WWW_USER | X18: 59 | Y18: 42626.967 | Z18: 41149.832
A19: CCCS | B19: City Campus-Compass Program | C19: 201310 | D19: -900 | F19: 0 | G19: R | H19: 41149.828 | I19: 41149.828 | O19: 43 | T19: F | U19: F0015930 | V19: 43510 | W19: WWW_USER | X19: 59 | Y19: 42626.967 | Z19: 41149.828
A20: LINX | B20: Linx Payment | C20: 201310 | E20: 410 | F20: 0 | G20: T | H20: 41148 | I20: 41148 | L20: 208483 | O20: 42 | T20: F | U20: F0004315 | V20: 41149 | W20: LBENJAMIN | X20: 483 | Y20: 41148.685 | Z20: 41148.569
A21: CCCS | B21: City Campus-Compass Program | C21: 201310 | D21: 900 | F21: 0 | G21: R | H21: 41133 | I21: 41133 | M21: Y | O21: 41 | T21: F | U21: F0015919 | V21: 43510 | W21: WWW_USER | X21: 59 | Y21: 42626.967 | Z21: 41133.579
A22: CCCS | B22: City Campus-Compass Program | C22: 201310 | D22: -900 | F22: 0 | G22: R | H22: 41133 | I22: 41133 | M22: Y | O22: 40 | T22: F | U22: F0015919 | V22: 43510 | W22: WWW_USER | X22: 59 | Y22: 42626.967 | Z22: 41133.578
A23: CCCS | B23: City Campus-Compass Program | C23: 201310 | D23: 900 | F23: 0 | G23: R | H23: 41129 | I23: 41129 | M23: Y | O23: 39 | T23: F | U23: F0015913 | V23: 43510 | W23: WWW_USER | X23: 59 | Y23: 42626.967 | Z23: 41129.991
A24: CCCS | B24: City Campus-Compass Program | C24: 201310 | D24: -900 | F24: 0 | G24: R | H24: 41129 | I24: 41129 | M24: Y | O24: 38 | T24: F | U24: F0015914 | V24: 43510 | W24: WWW_USER | X24: 59 | Y24: 42626.967 | Z24: 41129.99
A25: CCCS | B25: City Campus-Compass Program | C25: 201310 | D25: 900 | F25: 0 | G25: R | H25: 41129 | I25: 41129 | M25: Y | O25: 37 | T25: F | U25: F0015913 | V25: 43510 | W25: WWW_USER | X25: 59 | Y25: 42626.967 | Z25: 41129.988
A26: CCCS | B26: City Campus-Compass Program | C26: 201310 | D26: 900 | F26: 0 | G26: R | H26: 41129 | I26: 41129 | M26: Y | O26: 36 | T26: F | U26: F0015913 | V26: 43510 | W26: WWW_USER | X26: 59 | Y26: 42626.967 | Z26: 41129.987
A27: CCCS | B27: City Campus-Compass Program | C27: 201310 | D27: -900 | F27: 0 | G27: R | H27: 41129 | I27: 41129 | M27: Y | O27: 35 | T27: F | U27: F0015913 | V27: 43510 | W27: WWW_USER | X27: 59 | Y27: 42626.967 | Z27: 41129.986
A28: CCCS | B28: City Campus-Compass Program | C28: 201310 | D28: -900 | F28: 0 | G28: R | H28: 41129 | I28: 41129 | M28: Y | O28: 34 | T28: F | U28: F0015913 | V28: 43510 | W28: WWW_USER | X28: 59 | Y28: 42626.967 | Z28: 41129.986
A29: CSCS | B29: South Campus-Compass Program | C29: 201310 | D29: 900 | F29: 0 | G29: R | H29: 41129 | I29: 41129 | M29: Y | O29: 33 | T29: F | U29: F0015914 | V29: 43510 | W29: WWW_USER | X29: 59 | Y29: 42626.967 | Z29: 41129.986
A30: CCCS | B30: City Campus-Compass Program | C30: 201310 | D30: 900 | F30: 0 | G30: R | H30: 41129 | I30: 41129 | M30: Y | O30: 32 | T30: F | U30: F0015913 | V30: 43510 | W30: WWW_USER | X30: 59 | Y30: 42626.967 | Z30: 41129.985
A31: CSCS | B31: South Campus-Compass Program | C31: 201310 | D31: -900 | F31: 0 | G31: R | H31: 41129 | I31: 41129 | M31: Y | O31: 31 | T31: F | U31: F0015913 | V31: 43510 | W31: WWW_USER | X31: 59 | Y31: 42626.967 | Z31: 41129.984
A32: CCCS | B32: City Campus-Compass Program | C32: 201310 | D32: -900 | F32: 0 | G32: R | H32: 41129 | I32: 41129 | M32: Y | O32: 30 | T32: F | U32: F0015913 | V32: 43510 | W32: WWW_USER | X32: 59 | Y32: 42626.967 | Z32: 41129.984
... A61: CCAC | B61: City Campus-Student Insurance | C61: 201310 | D61: 30 | F61: 0 | G61: R | H61: 41127 | I61: 41127 | M61: Y | O61: 1 | T61: F | U61: F0015907 | V61: 43510 | W61: WWW_USER | X61: 59 | Y61: 42626.967 | Z61: 41127.548
A62: GATE | B62: GATE Payment | C62: 201320 | E62: 2700 | F62: 0 | G62: C | H62: 44039.576 | I62: 44039.576 | O62: 255 | T62: F | U62: F0018156 | V62: 44046 | W62: EPUJADAS | X62: 5 | Y62: 44039.634 | Z62: 44039.576
A63: GATE | B63: GATE Payment | C63: 201320 | E63: -2700 | F63: 0 | G63: C | H63: 44039.576 | I63: 44039.576 | O63: 254 | T63: F | U63: F0018156 | V63: 44046 | W63: EPUJADAS | X63: 5 | Y63: 44039.634 | Z63: 44039.576
A64: GATE | B64: GATE Payment CORR | C64: 201320 | E64: 2700 | F64: 0 | G64: C | H64: 43192.365 | I64: 43192.365 | O64: 148 | T64: F | W64: SAISUSR | X64: 2 | Y64: 43792.549 | Z64: 43192.365
A65: CCCS | B65: City Campus-Compass Program | C65: 201320 | D65: 900 | F65: 0 | G65: R | H65: 41303.79 | I65: 41303.79 | O65: 65 | T65: F | U65: F0015954 | V65: 43510 | W65: KANDERSON | X65: 47 | Y65: 42649.545 | Z65: 41303.79
A66: CCID | B66: City Campus-ID Card Rep Fee | C66: 201320 | D66: 15 | F66: 0 | G66: T | H66: 41289 | I66: 41289 | L66: 228570 | O66: 64 | T66: F | U66: F0005477 | V66: 41290 | W66: LBENJAMIN | X66: 625 | Y66: 41289.589 | Z66: 41289.516
A67: CASH | B67: Cash Payment | C67: 201320 | E67: 15 | F67: 0 | G67: T | H67: 41289 | I67: 41289 | L67: 228570 | O67: 63 | T67: F | U67: F0005477 | V67: 41290 | W67: LBENJAMIN | X67: 625 | Y67: 41289.589 | Z67: 41289.516
A68: CASH | B68: Cash Payment | C68: 201320 | E68: 280 | F68: 0 | G68: T | H68: 41282 | I68: 41282 | L68: 224720 | O68: 62 | T68: F | U68: F0005392 | V68: 41283 | W68: FCAMERON | X68: 1356 | Y68: 41282.594 | Z68: 41282.437
...
